Workbook

Sheet Mall Data
A1: Date | B1: Day Type | C1: Peak Time Slot | D1: Holiday? | E1: Total Footfalls | F1: AgeGroup%_Under18 | G1: AgeGroup%_18-25 | H1: AgeGroup%_26-40 | I1: AgeGroup%_Over40 | J1: %Male | K1: %Female | L1: Avg Spend Per Visitor (₹) | M1: Spend on Purchases (₹) | N1: Spend on Food (₹) | O1: Spend on Entertainment (₹) | P1: Movies Ticket Sold | Q1: Total Transactions | R1: Discount Usage Rate (%) | S1: Avg Duration of Stay (mins) | T1: Weather Conditions | U1: Traffic Conditions
A2: 44927 | B2: =IF(WEEKDAY(A2,2)=6,"Weekend",IF(WEEKDAY(A2,2)=7,"Weekend","Weekday")) -> Weekend | C2: Evening | D2: Yes | E2: 25459 | F2: 7 | G2: 33 | H2: 30 | I2: 30 | J2: 52 | K2: 48 | L2: =ROUND((M2+N2+O2)/E2,0) -> 1495 | M2: 16184249 | N2: 18902336 | O2: 2964686.1 | P2: 2564 | Q2: 7073 | R2: 14.55 | S2: 230 | T2: Sunny | U2: Low
A3: 44928 | B3: =IF(WEEKDAY(A3,2)=6,"Weekend",IF(WEEKDAY(A3,2)=7,"Weekend","Weekday")) -> Weekday | C3: Morning | D3: No | E3: 14593 | F3: 18 | G3: 46 | H3: 31 | I3: 5 | J3: 55 | K3: 45 | L3: =ROUND((M3+N3+O3)/E3,0) -> 1627 | M3: 9767331.9 | N3: 10653989 | O3: 3325936.5 | P3: 1708 | Q3: 7537 | R3: 21.77 | S3: 169 | T3: Rainy | U3: High
A4: 44929 | B4: =IF(WEEKDAY(A4,2)=6,"Weekend",IF(WEEKDAY(A4,2)=7,"Weekend","Weekday")) -> Weekday | C4: Morning | D4: No | E4: 17912 | F4: 13 | G4: 36 | H4: 39 | I4: 12 | J4: 51 | K4: 49 | L4: =ROUND((M4+N4+O4)/E4,0) -> 1877 | M4: 19478526 | N4: 12127846 | O4: 2008199.7 | P4: 1776 | Q4: 6460 | R4: 47.94 | S4: 225 | T4: Rainy | U4: High
A5: 44930 | B5: =IF(WEEKDAY(A5,2)=6,"Weekend",IF(WEEKDAY(A5,2)=7,"Weekend","Weekday")) -> Weekday | C5: Evening | D5: No | E5: 15301 | F5: 20 | G5: 34 | H5: 27 | I5: 19 | J5: 55 | K5: 45 | L5: =ROUND((M5+N5+O5)/E5,0) -> 2059 | M5: 17031526 | N5: 10783574 | O5: 3687956.4 | P5: 1455 | Q5: 9016 | R5: 35.49 | S5: 170 | T5: Rainy | U5: Low
A6: 44931 | B6: =IF(WEEKDAY(A6,2)=6,"Weekend",IF(WEEKDAY(A6,2)=7,"Weekend","Weekday")) -> Weekday | C6: Morning | D6: No | E6: 18676 | F6: 10 | G6: 33 | H6: 28 | I6: 29 | J6: 45 | K6: 55 | L6: =ROUND((M6+N6+O6)/E6,0) -> 1919 | M6: 22625888 | N6: 10165859 | O6: 3040063.9 | P6: 2131 | Q6: 4169 | R6: 12.24 | S6: 134 | T6: Cloudy | U6: Low
A7: 44932 | B7: =IF(WEEKDAY(A7,2)=6,"Weekend",IF(WEEKDAY(A7,2)=7,"Weekend","Weekday")) -> Weekday | C7: Morning | D7: No | E7: 13637 | F7: 14 | G7: 43 | H7: 32 | I7: 11 | J7: 54 | K7: 46 | L7: =ROUND((M7+N7+O7)/E7,0) -> 1477 | M7: 12299449 | N7: 4630608.5 | O7: 3216251.2 | P7: 3135 | Q7: 8298 | R7: 26.37 | S7: 80 | T7: Rainy | U7: Low
A8: 44933 | B8: =IF(WEEKDAY(A8,2)=6,"Weekend",IF(WEEKDAY(A8,2)=7,"Weekend","Weekday")) -> Weekend | C8: Afternoon | D8: No | E8: 40986 | F8: 16 | G8: 31 | H8: 33 | I8: 20 | J8: 47 | K8: 53 | L8: =ROUND((M8+N8+O8)/E8,0) -> 785 | M8: 18264680 | N8: 6362039.6 | O8: 7538331.9 | P8: 2661 | Q8: 9229 | R8: 47.99 | S8: 215 | T8: Cloudy | U8: Medium
A9: 44934 | B9: =IF(WEEKDAY(A9,2)=6,"Weekend",IF(WEEKDAY(A9,2)=7,"Weekend","Weekday")) -> Weekend | C9: Evening | D9: No | E9: 24064 | F9: 10 | G9: 35 | H9: 32 | I9: 23 | J9: 48 | K9: 52 | L9: =ROUND((M9+N9+O9)/E9,0) -> 1839 | M9: 32690481 | N9: 8658612 | O9: 2910173.9 | P9: 3007 | Q9: 7082 | R9: 21.4 | S9: 131 | T9: Sunny | U9: Medium
A10: 44935 | B10: =IF(WEEKDAY(A10,2)=6,"Weekend",IF(WEEKDAY(A10,2)=7,"Weekend","Weekday")) -> Weekday | C10: Morning | D10: No | E10: 8532 | F10: 10 | G10: 31 | H10: 32 | I10: 27 | J10: 54 | K10: 46 | L10: =ROUND((M10+N10+O10)/E10,0) -> 3272 | M10: 13559901 | N10: 10408505 | O10: 3951685 | P10: 748 | Q10: 8833 | R10: 25.08 | S10: 179 | T10: Sunny | U10: Medium
A11: 44936 | B11: =IF(WEEKDAY(A11,2)=6,"Weekend",IF(WEEKDAY(A11,2)=7,"Weekend","Weekday")) -> Weekday | C11: Evening | D11: No | E11: 12188 | F11: 19 | G11: 35 | H11: 31 | I11: 15 | J11: 45 | K11: 55 | L11: =ROUND((M11+N11+O11)/E11,0) -> 1291 | M11: 7351454.3 | N11: 5436132.6 | O11: 2952780.1 | P11: 2157 | Q11: 14316 | R11: 33.76 | S11: 239 | T11: Sunny | U11: Low
A12: 44937 | B12: =IF(WEEKDAY(A12,2)=6,"Weekend",IF(WEEKDAY(A12,2)=7,"Weekend","Weekday")) -> Weekday | C12: Evening | D12: No | E12: 19487 | F12: 20 | G12: 31 | H12: 25 | I12: 24 | J12: 45 | K12: 55 | L12: =ROUND((M12+N12+O12)/E12,0) -> 1334 | M12: 15247674 | N12: 6026885.6 | O12: 4718480.2 | P12: 927 | Q12: 8172 | R12: 24.9 | S12: 122 | T12: Rainy | U12: High
A13: 44938 | B13: =IF(WEEKDAY(A13,2)=6,"Weekend",IF(WEEKDAY(A13,2)=7,"Weekend","Weekday")) -> Weekday | C13: Evening | D13: No | E13: 8031 | F13: 11 | G13: 49 | H13: 27 | I13: 13 | J13: 55 | K13: 45 | L13: =ROUND((M13+N13+O13)/E13,0) -> 1760 | M13: 8710225.5 | N13: 4055975.7 | O13: 1370408.4 | P13: 1922 | Q13: 7635 | R13: 39.59 | S13: 80 | T13: Rainy | U13: High
... A366: 45291 | B366: =IF(WEEKDAY(A366,2)=6,"Weekend",IF(WEEKDAY(A366,2)=7,"Weekend","Weekday")) -> Weekend | C366: Afternoon | D366: No | E366: 30142 | F366: 7 | G366: 42 | H366: 25 | I366: 26 | J366: 51 | K366: 49 | L366: =ROUND((M366+N366+O366)/E366,0) -> 1519 | M366: 26389336 | N366: 15758613 | O366: 3625514 | P366: 3259 | Q366: 12833 | R366: 16.85 | S366: 173 | T366: Cloudy | U366: Low

Sheet Task 1
B1: Total Footfall | O1: Total Footfall
B2: Weekday | C2: Weekend | O2: Weekday | P2: Weekend
A3: Mean | B3: =AVERAGEIF('Mall Data'!B:B,"Weekday",'Mall Data'!E:E) -> 14964.488 | C3: =AVERAGEIF('Mall Data'!B:B,"Weekend",'Mall Data'!E:E) -> 28018.324 | O3: 14593 | P3: 25459
A4: Median | B4: {=MEDIAN(IF('Mall Data'!B:B="Weekday",'Mall Data'!E:E))} -> 14039.5 | C4: {=MEDIAN(IF('Mall Data'!B:B="Weekend",'Mall Data'!E:E))} -> 28345 | O4: 17912 | P4: 40986
A5: Mode | B5: {=MODE(IF('Mall Data'!B:B="Weekday",'Mall Data'!E:E))} -> 13500 | C5: {=MODE(IF('Mall Data'!B:B="Weekend",'Mall Data'!E:E))} -> 33673 | O5: 15301 | P5: 24064
A6: Comparision | B6: Mean>Median>Mode | C6: Mean<Median<Mode | O6: 18676 | P6: 22911
A7: Skewness | B7: Right- skewed | C7: Right- skewed | O7: 13637 | P7: 29735
O8: 8532 | P8: 31707
O9: 12188 | P9: 29219
O10: 19487 | P10: 32041
O11: 8031 | P11: 34172
O12: 13022 | P12: 21683
O13: 9712 | P13: 32985
O14: 16160 | P14: 22113
O15: 14179 | P15: 29637
O16: 17045 | P16: 29223
O17: 17275 | P17: 27823
O18: 18194 | P18: 31669
O19: 13707 | P19: 23675
... O107: 16835 | P107: 30142
O108: 10087
O109: 12757
O110: 10766
O111: 9434
O112: 10397
O113: 17177
O114: 12886
O115: 12804
O116: 10028
O117: 13499
O118: 15354
O119: 14596
... O262: 16113

Sheet Task 2
B1: Movie Ticket Sold | O1: Movie Ticket Sold
B2: Morning | C2: Afternoon | D2: Evening | O2: Morning | P2: Afternoon | Q2: Evening
A3: Mean | B3: =AVERAGE(O3:O121) -> 2126.0084 | C3: =AVERAGE(P3:P60) -> 2182.2759 | D3: =AVERAGE(Q3:Q190) -> 2307.1011 | O3: 1708 | P3: 2661 | Q3: 2564
A4: Median | B4: =MEDIAN(O3:O121) -> 2121 | C4: =MEDIAN(P3:P60) -> 2102 | D4: =MEDIAN(Q3:Q190) -> 2438 | O4: 1776 | P4: 1333 | Q4: 1455
A5: Mode | B5: =MODE(O3:O121) -> 2210 | C5: =MODE(P3:P60) -> 2099 | D5: =MODE(Q3:Q190) -> 1455 | O5: 2131 | P5: 3897 | Q5: 3007
A6: Comparison | B6: Mean>Median<mode | C6: Mean>Median>Mode | D6: Mean<Median>Mode | O6: 3135 | P6: 3566 | Q6: 2157
A7: Skewness | B7: lightly right skewness(+ve) | C7: Right skewness(+ve) | D7: left skewness(negative) | O7: 748 | P7: 2105 | Q7: 927
O8: 1701 | P8: 1059 | Q8: 1922
O9: 2328 | P9: 2099 | Q9: 1561
O10: 1793 | P10: 622 | Q10: 2978
O11: 1890 | P11: 2357 | Q11: 3738
O12: 3123 | P12: 2088 | Q12: 3490
O13: 534 | P13: 3996 | Q13: 593
O14: 1002 | P14: 1901 | Q14: 1708
O15: 885 | P15: 2787 | Q15: 3816
O16: 2935 | P16: 623 | Q16: 2570
O17: 1300 | P17: 1102 | Q17: 3134
O18: 2527 | P18: 2215 | Q18: 3978
O19: 3176 | P19: 512 | Q19: 1329
... O60: 972 | P60: 3259 | Q60: 559
O61: 3170 | Q61: 2626
O62: 2650 | Q62: 1455
O63: 3954 | Q63: 532
O64: 2577 | Q64: 3001
O65: 2498 | Q65: 3575
O66: 1121 | Q66: 1828
O67: 3402 | Q67: 1486
O68: 3477 | Q68: 2404
O69: 1243 | Q69: 3930
O70: 1819 | Q70: 3391
O71: 977 | Q71: 1440
O72: 1904 | Q72: 2882
... O121: 1621 | Q121: 2211
Q122: 2891
Q123: 2920
Q124: 3686
Q125: 1400
Q126: 3556
Q127: 3680
Q128: 3298
...

Sheet Task 3
B1: Avg Duration of Stay (min) | R1: Avg Duration of Stay (mins)
B2: Not Holiday | C2: Holiday | R2: Not Holiday | S2: Holiday
A3: Mean | B3: =AVERAGE(R3:R353) -> 154.57265 | C3: =AVERAGE(S3:S16) -> 206.35714 | R3: 169 | S3: 230
A4: Median | B4: =MEDIAN(R3:R353) -> 154 | C4: =MEDIAN(S3:S16) -> 225.5 | R4: 225 | S4: 214
A5: Mode | B5: =MODE(R3:R353) -> 152 | C5: =MODE(S3:S16) -> 230 | R5: 170 | S5: 279
A6: Comparision | B6: Mean>Median>Mode | C6: Mean>Median>Mode | R6: 134 | S6: 230
A7: Skewness | B7: Slightly right skewed | C7: Slightly Left skewed | R7: 80 | S7: 108
R8: 215 | S8: 221
R9: 131 | S9: 139
R10: 179 | S10: 207
R11: 239 | S11: 115
R12: 122 | S12: 237
R13: 80 | S13: 263
R14: 237 | S14: 233
R15: 236 | S15: 183
R16: 175 | S16: 230
R17: 87
R18: 137
R19: 113
R20: 211
R21: 202
R22: 166
R23: 231
R24: 204
R25: 170
R26: 152
R27: 132
R28: 119
... R353: 173
